<sdf version='1.7'>
  <model name='HnuRobot'>
    <plugin name="my_robot_plugin" filename="libd_drive_car.so">
      <wheelSeparation>0.2</wheelSeparation>
    </plugin>
    <link name='base_footprint'>
      <inertial>
        <pose>0 0 0.084091 0 -0 0</pose>
        <mass>1.1</mass>
        <inertia>
          <ixx>0.00423533</ixx>
          <ixy>0</ixy>
          <ixz>0</ixz>
          <iyy>0.00487533</iyy>
          <iyz>0</iyz>
          <izz>0.00565024</izz>
        </inertia>
      </inertial>
      <collision name='base_footprint_fixed_joint_lump__base_link_collision'>
        <pose>0 0 0.091 0 -0 0</pose>
        <geometry>
          <cylinder>
            <length>0.12</length>
            <radius>0.1</radius>
          </cylinder>
        </geometry>
      </collision>
      <collision name='base_footprint_fixed_joint_lump__back_caster_link_collision_1'>
        <pose>-0.08 0 0.015 0 -0 0</pose>
        <geometry>
          <sphere>
            <radius>0.016</radius>
          </sphere>
        </geometry>
        <surface>
          <contact>
            <ode>
              <kp>1e+09</kp>
              <kd>1</kd>
            </ode>
          </contact>
          <friction>
            <ode>
              <mu>0</mu>
              <mu2>0</mu2>
            </ode>
          </friction>
        </surface>
      </collision>
      <collision name='base_footprint_fixed_joint_lump__front_caster_link_collision_2'>
        <pose>0.08 0 0.015 0 -0 0</pose>
        <geometry>
          <sphere>
            <radius>0.016</radius>
          </sphere>
        </geometry>
        <surface>
          <contact>
            <ode>
              <kp>1e+09</kp>
              <kd>1</kd>
            </ode>
          </contact>
          <friction>
            <ode>
              <mu>0</mu>
              <mu2>0</mu2>
            </ode>
          </friction>
        </surface>
      </collision>
      <visual name='base_footprint_fixed_joint_lump__base_link_visual'>
        <pose>0 0 0.091 0 -0 0</pose>
        <geometry>
          <cylinder>
            <length>0.12</length>
            <radius>0.1</radius>
          </cylinder>
        </geometry>
      </visual>
      <visual name='base_footprint_fixed_joint_lump__back_caster_link_visual_1'>
        <pose>-0.08 0 0.015 0 -0 0</pose>
        <geometry>
          <sphere>
            <radius>0.016</radius>
          </sphere>
        </geometry>
      </visual>
      <visual name='base_footprint_fixed_joint_lump__front_caster_link_visual_2'>
        <pose>0.08 0 0.015 0 -0 0</pose>
        <geometry>
          <sphere>
            <radius>0.016</radius>
          </sphere>
        </geometry>
      </visual>
    </link>
    <joint name='left_wheel_joint' type='revolute'>
      <pose relative_to='base_footprint'>0 0.1 0.031 0 -0 0</pose>
      <parent>base_footprint</parent>
      <child>left_wheel_link</child>
      <axis>
        <xyz>0 1 0</xyz>
        <limit>
          <lower>-1e+16</lower>
          <upper>1e+16</upper>
        </limit>
        <dynamics>
          <spring_reference>0</spring_reference>
          <spring_stiffness>0</spring_stiffness>
        </dynamics>
      </axis>
    </joint>
    <link name='left_wheel_link'>
      <pose relative_to='left_wheel_joint'>0 0 0 0 -0 0</pose>
      <inertial>
        <pose>0 0 0 0 -0 0</pose>
        <mass>0.05</mass>
        <inertia>
          <ixx>1.94667e-05</ixx>
          <ixy>0</ixy>
          <ixz>0</ixz>
          <iyy>1.94667e-05</iyy>
          <iyz>0</iyz>
          <izz>2.56e-05</izz>
        </inertia>
      </inertial>
      <collision name='left_wheel_link_collision'>
        <pose>0 0 0 1.57079 -0 0</pose>
        <geometry>
          <cylinder>
            <length>0.04</length>
            <radius>0.032</radius>
          </cylinder>
        </geometry>
        <surface>
          <contact>
            <ode>
              <kp>1e+09</kp>
              <kd>1</kd>
            </ode>
          </contact>
          <friction>
            <ode>
              <mu>20</mu>
              <mu2>20</mu2>
            </ode>
          </friction>
        </surface>
      </collision>
      <visual name='left_wheel_link_visual'>
        <pose>0 0 0 1.57079 -0 0</pose>
        <geometry>
          <cylinder>
            <length>0.04</length>
            <radius>0.032</radius>
          </cylinder>
        </geometry>
      </visual>
    </link>
    <joint name='right_wheel_joint' type='revolute'>
      <pose relative_to='base_footprint'>0 -0.1 0.031 0 -0 0</pose>
      <parent>base_footprint</parent>
      <child>right_wheel_link</child>
      <axis>
        <xyz>0 1 0</xyz>
        <limit>
          <lower>-1e+16</lower>
          <upper>1e+16</upper>
        </limit>
        <dynamics>
          <spring_reference>0</spring_reference>
          <spring_stiffness>0</spring_stiffness>
        </dynamics>
      </axis>
    </joint>
    <link name='right_wheel_link'>
      <pose relative_to='right_wheel_joint'>0 0 0 0 -0 0</pose>
      <inertial>
        <pose>0 0 0 0 -0 0</pose>
        <mass>0.05</mass>
        <inertia>
          <ixx>1.94667e-05</ixx>
          <ixy>0</ixy>
          <ixz>0</ixz>
          <iyy>1.94667e-05</iyy>
          <iyz>0</iyz>
          <izz>2.56e-05</izz>
        </inertia>
      </inertial>
      <collision name='right_wheel_link_collision'>
        <pose>0 0 0 1.57079 -0 0</pose>
        <geometry>
          <cylinder>
            <length>0.04</length>
            <radius>0.032</radius>
          </cylinder>
        </geometry>
        <surface>
          <contact>
            <ode>
              <kp>1e+09</kp>
              <kd>1</kd>
            </ode>
          </contact>
          <friction>
            <ode>
              <mu>20</mu>
              <mu2>20</mu2>
            </ode>
          </friction>
        </surface>
      </collision>
      <visual name='right_wheel_link_visual'>
        <pose>0 0 0 1.57079 -0 0</pose>
        <geometry>
          <cylinder>
            <length>0.04</length>
            <radius>0.032</radius>
          </cylinder>
        </geometry>
      </visual>
    </link>
  </model>
</sdf>
