<?xml version="1.0" ?>
<!-- =================================================================================== -->
<!-- |    This document was autogenerated by xacro from fishbot.urdf.xacro             | -->
<!-- |    EDITING THIS FILE BY HAND IS NOT RECOMMENDED                                 | -->
<!-- =================================================================================== -->
<robot name="fishbot">
  v

  <link name="base_footprint"/>
  <!-- 机器人身体部分 -->
  <link name="base_link">
    <!--部件外观描述-->
    <visual>
      <!--沿着自己几何中心的偏移和旋转-->
      <origin rpy="0 0 0" xyz="0 0 0"/>
      <!--几何形状-->
      <geometry>
        <!--圆柱体 radius 半径 0.10m 高度 length 0.12m-->
        <cylinder length="0.12" radius="0.1"/>
      </geometry>
      <!--材质-->
      <material name="white">
        <color rgba="1.0 1.0 1.0 0.5"/>
      </material>
    </visual>
    <collision>
      <!--沿着自己几何中心的偏移和旋转-->
      <origin rpy="0 0 0" xyz="0 0 0"/>
      <!--几何形状-->
      <geometry>
        <!--圆柱体 radius 半径 0.10m 高度 length 0.12m-->
        <cylinder length="0.12" radius="0.1"/>
      </geometry>
      <!--材质-->
      <material name="white">
        <color rgba="1.0 1.0 1.0 0.5"/>
      </material>
    </collision>
    <inertial>
      <mass value="1.0"/>
      <inertia ixx="0.0037000000000000006" ixy="0" ixz="0" iyy="0.0037000000000000006" iyz="0" izz="0.005000000000000001"/>
    </inertial>
  </link>
  <joint name="joint_name" type="fixed">
    <!--关节连接的部件-->
    <parent link="base_footprint"/>
    <child link="base_link"/>
    <!--关节的偏移和旋转-->
    <origin rpy="0 0 0" xyz="0 0 0.091"/>
  </joint>
  <!-- 机器人IMU部件，惯性测量传感器 -->
  <link name="left_wheel_link">
    <!--部件外观描述-->
    <visual>
      <!--沿着自己几何中心的偏移和旋转-->
      <origin rpy="1.57079 0 0" xyz="0 0 0"/>
      <!--几何形状-->
      <geometry>
        <cylinder length="0.04" radius="0.032"/>
      </geometry>
      <!--材质-->
      <material name="yellow">
        <color rgba="1.0 1.0 0.0 0.8"/>
      </material>
    </visual>
    <collision>
      <!--沿着自己几何中心的偏移和旋转-->
      <origin rpy="1.57079 0 0" xyz="0 0 0"/>
      <!--几何形状-->
      <geometry>
        <cylinder length="0.04" radius="0.032"/>
      </geometry>
      <!--材质-->
      <material name="yellow">
        <color rgba="1.0 1.0 0.0 0.8"/>
      </material>
    </collision>
    <inertial>
      <mass value="0.05"/>
      <inertia ixx="1.9466666666666668e-05" ixy="0" ixz="0" iyy="1.9466666666666668e-05" iyz="0" izz="2.56e-05"/>
    </inertial>
  </link>
  <!--机器人关节，用于组合机器人的部分-->
  <joint name="left_wheel_joint" type="continuous">
    <!--关节连接的部件-->
    <parent link="base_link"/>
    <child link="left_wheel_link"/>
    <!--关节的偏移和旋转-->
    <origin rpy="0 0 0" xyz="0 0.10 -0.06"/>
    <axis xyz="0.0 1.0 0.0"/>
  </joint>
  <gazebo reference="left_wheel_link">
    <mu1 value="20.0"/>
    <mu2 value="20.0"/>
    <kp value="1000000000.0"/>
    <kd value="1.0"/>
  </gazebo>
  <!-- 机器人IMU部件，惯性测量传感器 -->
  <link name="right_wheel_link">
    <!--部件外观描述-->
    <visual>
      <!--沿着自己几何中心的偏移和旋转-->
      <origin rpy="1.57079 0 0" xyz="0 0 0"/>
      <!--几何形状-->
      <geometry>
        <cylinder length="0.04" radius="0.032"/>
      </geometry>
      <!--材质-->
      <material name="yellow">
        <color rgba="1.0 1.0 0.0 0.8"/>
      </material>
    </visual>
    <collision>
      <!--沿着自己几何中心的偏移和旋转-->
      <origin rpy="1.57079 0 0" xyz="0 0 0"/>
      <!--几何形状-->
      <geometry>
        <cylinder length="0.04" radius="0.032"/>
      </geometry>
      <!--材质-->
      <material name="yellow">
        <color rgba="1.0 1.0 0.0 0.8"/>
      </material>
    </collision>
    <inertial>
      <mass value="0.05"/>
      <inertia ixx="1.9466666666666668e-05" ixy="0" ixz="0" iyy="1.9466666666666668e-05" iyz="0" izz="2.56e-05"/>
    </inertial>
  </link>
  <!--机器人关节，用于组合机器人的部分-->
  <joint name="right_wheel_joint" type="continuous">
    <!--关节连接的部件-->
    <parent link="base_link"/>
    <child link="right_wheel_link"/>
    <!--关节的偏移和旋转-->
    <origin rpy="0 0 0" xyz="0 -0.10 -0.06"/>
    <axis xyz="0.0 1.0 0.0"/>
  </joint>
  <gazebo reference="right_wheel_link">
    <mu1 value="20.0"/>
    <mu2 value="20.0"/>
    <kp value="1000000000.0"/>
    <kd value="1.0"/>
  </gazebo>
  <!-- 机器人IMU部件，惯性测量传感器 -->
  <link name="front_caster_link">
    <!--部件外观描述-->
    <visual>
      <!--沿着自己几何中心的偏移和旋转-->
      <origin rpy="0 0 0" xyz="0 0 0"/>
      <!--几何形状-->
      <geometry>
        <sphere radius="0.016"/>
      </geometry>
      <!--材质-->
      <material name="yellow">
        <color rgba="1.0 1.0 0.0 0.8"/>
      </material>
    </visual>
    <collision>
      <!--沿着自己几何中心的偏移和旋转-->
      <origin rpy="0 0 0" xyz="0 0 0"/>
      <!--几何形状-->
      <geometry>
        <sphere radius="0.016"/>
      </geometry>
      <!--材质-->
      <material name="yellow">
        <color rgba="1.0 1.0 0.0 0.8"/>
      </material>
    </collision>
    <inertial>
      <mass value="0.05"/>
      <inertia ixx="5.120000000000001e-06" ixy="0.0" ixz="0.0" iyy="5.120000000000001e-06" iyz="0.0" izz="5.120000000000001e-06"/>
    </inertial>
  </link>
  <!--机器人关节，用于组合机器人的部分-->
  <joint name="front_caster_joint" type="fixed">
    <!--关节连接的部件-->
    <parent link="base_link"/>
    <child link="front_caster_link"/>
    <!--关节的偏移和旋转-->
    <origin rpy="0 0 0" xyz="0.08 0.0 -0.076"/>
  </joint>
  <gazebo reference="front_caster_link">
    <mu1 value="0.0"/>
    <mu2 value="0.0"/>
    <kp value="1000000000.0"/>
    <kd value="1.0"/>
  </gazebo>
  <!-- 机器人IMU部件，惯性测量传感器 -->
  <link name="back_caster_link">
    <!--部件外观描述-->
    <visual>
      <!--沿着自己几何中心的偏移和旋转-->
      <origin rpy="0 0 0" xyz="0 0 0"/>
      <!--几何形状-->
      <geometry>
        <sphere radius="0.016"/>
      </geometry>
      <!--材质-->
      <material name="yellow">
        <color rgba="1.0 1.0 0.0 0.8"/>
      </material>
    </visual>
    <collision>
      <!--沿着自己几何中心的偏移和旋转-->
      <origin rpy="0 0 0" xyz="0 0 0"/>
      <!--几何形状-->
      <geometry>
        <sphere radius="0.016"/>
      </geometry>
      <!--材质-->
      <material name="yellow">
        <color rgba="1.0 1.0 0.0 0.8"/>
      </material>
    </collision>
    <inertial>
      <mass value="0.05"/>
      <inertia ixx="5.120000000000001e-06" ixy="0.0" ixz="0.0" iyy="5.120000000000001e-06" iyz="0.0" izz="5.120000000000001e-06"/>
    </inertial>
  </link>
  <!--机器人关节，用于组合机器人的部分-->
  <joint name="back_caster_joint" type="fixed">
    <!--关节连接的部件-->
    <parent link="base_link"/>
    <child link="back_caster_link"/>
    <!--关节的偏移和旋转-->
    <origin rpy="0 0 0" xyz="-0.08 0.0 -0.076"/>
  </joint>
  <gazebo reference="back_caster_link">
    <mu1 value="0.0"/>
    <mu2 value="0.0"/>
    <kp value="1000000000.0"/>
    <kd value="1.0"/>
  </gazebo>
</robot>
